[2024-01-31 13:41:25,675] {taskinstance.py:1159} INFO - Dependencies all met for <TaskInstance: etl_postgresql.aggregate_dim_table manual__2024-01-31T13:41:09.078541+00:00 [queued]>
[2024-01-31 13:41:25,682] {taskinstance.py:1159} INFO - Dependencies all met for <TaskInstance: etl_postgresql.aggregate_dim_table manual__2024-01-31T13:41:09.078541+00:00 [queued]>
[2024-01-31 13:41:25,682] {taskinstance.py:1356} INFO - 
--------------------------------------------------------------------------------
[2024-01-31 13:41:25,682] {taskinstance.py:1357} INFO - Starting attempt 1 of 2
[2024-01-31 13:41:25,682] {taskinstance.py:1358} INFO - 
--------------------------------------------------------------------------------
[2024-01-31 13:41:25,690] {taskinstance.py:1377} INFO - Executing <Task(PythonOperator): aggregate_dim_table> on 2024-01-31 13:41:09.078541+00:00
[2024-01-31 13:41:25,694] {standard_task_runner.py:52} INFO - Started process 6608 to run task
[2024-01-31 13:41:25,697] {standard_task_runner.py:79} INFO - Running: ['***', 'tasks', 'run', 'etl_postgresql', 'aggregate_dim_table', 'manual__2024-01-31T13:41:09.078541+00:00', '--job-id', '130', '--raw', '--subdir', 'DAGS_FOLDER/etl_dag.py', '--cfg-path', '/tmp/tmpheqslpxu', '--error-file', '/tmp/tmppanifah3']
[2024-01-31 13:41:25,698] {standard_task_runner.py:80} INFO - Job 130: Subtask aggregate_dim_table
[2024-01-31 13:41:25,733] {task_command.py:369} INFO - Running <TaskInstance: etl_postgresql.aggregate_dim_table manual__2024-01-31T13:41:09.078541+00:00 [running]> on host d99f9e65d396
[2024-01-31 13:41:25,782] {taskinstance.py:1571} INFO - Exporting the following env vars:
AIRFLOW_CTX_DAG_OWNER=***
AIRFLOW_CTX_DAG_ID=etl_postgresql
AIRFLOW_CTX_TASK_ID=aggregate_dim_table
AIRFLOW_CTX_EXECUTION_DATE=2024-01-31T13:41:09.078541+00:00
AIRFLOW_CTX_TRY_NUMBER=1
AIRFLOW_CTX_DAG_RUN_ID=manual__2024-01-31T13:41:09.078541+00:00
[2024-01-31 13:41:28,882] {logging_mixin.py:115} INFO - Successfully install sqlalchemy
[2024-01-31 13:41:31,934] {logging_mixin.py:115} INFO - Successfully install pymysql
[2024-01-31 13:41:32,002] {taskinstance.py:1889} ERROR - Task failed with exception
Traceback (most recent call last):
  File "/home/airflow/.local/lib/python3.7/site-packages/airflow/operators/python.py", line 171, in execute
    return_value = self.execute_callable()
  File "/home/airflow/.local/lib/python3.7/site-packages/airflow/operators/python.py", line 189, in execute_callable
    return self.python_callable(*self.op_args, **self.op_kwargs)
  File "/opt/airflow/dags/etl_dag.py", line 191, in _aggregate_dim_table
    class StagingData(Base):
  File "/home/airflow/.local/lib/python3.7/site-packages/sqlalchemy/orm/decl_api.py", line 75, in __init__
    _as_declarative(reg, cls, dict_)
  File "/home/airflow/.local/lib/python3.7/site-packages/sqlalchemy/orm/decl_base.py", line 126, in _as_declarative
    return _MapperConfig.setup_mapping(registry, cls, dict_, None, {})
  File "/home/airflow/.local/lib/python3.7/site-packages/sqlalchemy/orm/decl_base.py", line 177, in setup_mapping
    return cfg_cls(registry, cls_, dict_, table, mapper_kw)
  File "/home/airflow/.local/lib/python3.7/site-packages/sqlalchemy/orm/decl_base.py", line 314, in __init__
    self._early_mapping(mapper_kw)
  File "/home/airflow/.local/lib/python3.7/site-packages/sqlalchemy/orm/decl_base.py", line 200, in _early_mapping
    self.map(mapper_kw)
  File "/home/airflow/.local/lib/python3.7/site-packages/sqlalchemy/orm/decl_base.py", line 977, in map
    mapper_cls(self.cls, self.local_table, **self.mapper_args),
  File "<string>", line 2, in __init__
  File "/home/airflow/.local/lib/python3.7/site-packages/sqlalchemy/util/deprecations.py", line 298, in warned
    return fn(*args, **kwargs)
  File "/home/airflow/.local/lib/python3.7/site-packages/sqlalchemy/orm/mapper.py", line 686, in __init__
    self._configure_pks()
  File "/home/airflow/.local/lib/python3.7/site-packages/sqlalchemy/orm/mapper.py", line 1331, in _configure_pks
    % (self, self.persist_selectable.description)
sqlalchemy.exc.ArgumentError: Mapper mapped class StagingData->staging_covid_dataset could not assemble any primary key columns for mapped table 'staging_covid_dataset'
[2024-01-31 13:41:32,012] {taskinstance.py:1400} INFO - Marking task as UP_FOR_RETRY. dag_id=etl_postgresql, task_id=aggregate_dim_table, execution_date=20240131T134109, start_date=20240131T134125, end_date=20240131T134132
[2024-01-31 13:41:32,023] {standard_task_runner.py:97} ERROR - Failed to execute job 130 for task aggregate_dim_table (Mapper mapped class StagingData->staging_covid_dataset could not assemble any primary key columns for mapped table 'staging_covid_dataset'; 6608)
[2024-01-31 13:41:32,068] {local_task_job.py:156} INFO - Task exited with return code 1
[2024-01-31 13:41:32,093] {local_task_job.py:273} INFO - 0 downstream tasks scheduled from follow-on schedule check
