[2024-01-31 14:42:39,009] {taskinstance.py:1159} INFO - Dependencies all met for <TaskInstance: etl_postgresql.aggregate_dim_table manual__2024-01-31T14:42:15.608617+00:00 [queued]>
[2024-01-31 14:42:39,015] {taskinstance.py:1159} INFO - Dependencies all met for <TaskInstance: etl_postgresql.aggregate_dim_table manual__2024-01-31T14:42:15.608617+00:00 [queued]>
[2024-01-31 14:42:39,015] {taskinstance.py:1356} INFO - 
--------------------------------------------------------------------------------
[2024-01-31 14:42:39,015] {taskinstance.py:1357} INFO - Starting attempt 1 of 2
[2024-01-31 14:42:39,015] {taskinstance.py:1358} INFO - 
--------------------------------------------------------------------------------
[2024-01-31 14:42:39,025] {taskinstance.py:1377} INFO - Executing <Task(PythonOperator): aggregate_dim_table> on 2024-01-31 14:42:15.608617+00:00
[2024-01-31 14:42:39,028] {standard_task_runner.py:52} INFO - Started process 8088 to run task
[2024-01-31 14:42:39,031] {standard_task_runner.py:79} INFO - Running: ['***', 'tasks', 'run', 'etl_postgresql', 'aggregate_dim_table', 'manual__2024-01-31T14:42:15.608617+00:00', '--job-id', '156', '--raw', '--subdir', 'DAGS_FOLDER/etl_dag.py', '--cfg-path', '/tmp/tmptnp2l7ve', '--error-file', '/tmp/tmpe77irvea']
[2024-01-31 14:42:39,032] {standard_task_runner.py:80} INFO - Job 156: Subtask aggregate_dim_table
[2024-01-31 14:42:39,067] {task_command.py:369} INFO - Running <TaskInstance: etl_postgresql.aggregate_dim_table manual__2024-01-31T14:42:15.608617+00:00 [running]> on host d99f9e65d396
[2024-01-31 14:42:39,112] {taskinstance.py:1571} INFO - Exporting the following env vars:
AIRFLOW_CTX_DAG_OWNER=***
AIRFLOW_CTX_DAG_ID=etl_postgresql
AIRFLOW_CTX_TASK_ID=aggregate_dim_table
AIRFLOW_CTX_EXECUTION_DATE=2024-01-31T14:42:15.608617+00:00
AIRFLOW_CTX_TRY_NUMBER=1
AIRFLOW_CTX_DAG_RUN_ID=manual__2024-01-31T14:42:15.608617+00:00
[2024-01-31 14:42:41,952] {logging_mixin.py:115} INFO - Successfully install sqlalchemy
[2024-01-31 14:42:44,754] {logging_mixin.py:115} INFO - Successfully install pymysql
[2024-01-31 14:42:47,603] {logging_mixin.py:115} INFO - Successfully install sqlalchemy
[2024-01-31 14:42:50,551] {logging_mixin.py:115} INFO - Successfully install pymysql
[2024-01-31 14:42:53,560] {logging_mixin.py:115} INFO - Successfully install sqlalchemy
[2024-01-31 14:42:53,597] {logging_mixin.py:115} INFO - 32
[2024-01-31 14:42:53,597] {taskinstance.py:1889} ERROR - Task failed with exception
Traceback (most recent call last):
  File "/home/airflow/.local/lib/python3.7/site-packages/airflow/operators/python.py", line 171, in execute
    return_value = self.execute_callable()
  File "/home/airflow/.local/lib/python3.7/site-packages/airflow/operators/python.py", line 189, in execute_callable
    return self.python_callable(*self.op_args, **self.op_kwargs)
  File "/opt/airflow/dags/etl_dag.py", line 220, in _aggregate_dim_table
    print(row.nama_prov)
AttributeError: Could not locate column in row for column 'nama_prov'
[2024-01-31 14:42:53,605] {taskinstance.py:1400} INFO - Marking task as UP_FOR_RETRY. dag_id=etl_postgresql, task_id=aggregate_dim_table, execution_date=20240131T144215, start_date=20240131T144239, end_date=20240131T144253
[2024-01-31 14:42:53,614] {standard_task_runner.py:97} ERROR - Failed to execute job 156 for task aggregate_dim_table (Could not locate column in row for column 'nama_prov'; 8088)
[2024-01-31 14:42:53,638] {local_task_job.py:156} INFO - Task exited with return code 1
[2024-01-31 14:42:53,659] {local_task_job.py:273} INFO - 0 downstream tasks scheduled from follow-on schedule check
