[2024-02-01 11:42:39,498] {taskinstance.py:1159} INFO - Dependencies all met for <TaskInstance: etl_postgresql.create_ddl_postgres scheduled__2024-01-30T23:00:00+00:00 [queued]>
[2024-02-01 11:42:39,504] {taskinstance.py:1159} INFO - Dependencies all met for <TaskInstance: etl_postgresql.create_ddl_postgres scheduled__2024-01-30T23:00:00+00:00 [queued]>
[2024-02-01 11:42:39,504] {taskinstance.py:1356} INFO - 
--------------------------------------------------------------------------------
[2024-02-01 11:42:39,505] {taskinstance.py:1357} INFO - Starting attempt 2 of 2
[2024-02-01 11:42:39,505] {taskinstance.py:1358} INFO - 
--------------------------------------------------------------------------------
[2024-02-01 11:42:39,514] {taskinstance.py:1377} INFO - Executing <Task(PythonOperator): create_ddl_postgres> on 2024-01-30 23:00:00+00:00
[2024-02-01 11:42:39,518] {standard_task_runner.py:52} INFO - Started process 428 to run task
[2024-02-01 11:42:39,520] {standard_task_runner.py:79} INFO - Running: ['***', 'tasks', 'run', 'etl_postgresql', 'create_ddl_postgres', 'scheduled__2024-01-30T23:00:00+00:00', '--job-id', '221', '--raw', '--subdir', 'DAGS_FOLDER/etl_dag.py', '--cfg-path', '/tmp/tmpvn8h6xj2', '--error-file', '/tmp/tmp61sll0lq']
[2024-02-01 11:42:39,522] {standard_task_runner.py:80} INFO - Job 221: Subtask create_ddl_postgres
[2024-02-01 11:42:39,562] {task_command.py:369} INFO - Running <TaskInstance: etl_postgresql.create_ddl_postgres scheduled__2024-01-30T23:00:00+00:00 [running]> on host 0cb2a3b23a40
[2024-02-01 11:42:39,612] {taskinstance.py:1571} INFO - Exporting the following env vars:
AIRFLOW_CTX_DAG_OWNER=***
AIRFLOW_CTX_DAG_ID=etl_postgresql
AIRFLOW_CTX_TASK_ID=create_ddl_postgres
AIRFLOW_CTX_EXECUTION_DATE=2024-01-30T23:00:00+00:00
AIRFLOW_CTX_TRY_NUMBER=2
AIRFLOW_CTX_DAG_RUN_ID=scheduled__2024-01-30T23:00:00+00:00
[2024-02-01 11:42:42,492] {logging_mixin.py:115} INFO - Successfully install sqlalchemy
[2024-02-01 11:42:45,389] {logging_mixin.py:115} INFO - Successfully install sqlalchemy
[2024-02-01 11:44:00,427] {taskinstance.py:1889} ERROR - Task failed with exception
Traceback (most recent call last):
  File "/home/airflow/.local/lib/python3.7/site-packages/sqlalchemy/engine/base.py", line 3141, in _wrap_pool_connect
    return fn()
  File "/home/airflow/.local/lib/python3.7/site-packages/sqlalchemy/pool/base.py", line 301, in connect
    return _ConnectionFairy._checkout(self)
  File "/home/airflow/.local/lib/python3.7/site-packages/sqlalchemy/pool/base.py", line 755, in _checkout
    fairy = _ConnectionRecord.checkout(pool)
  File "/home/airflow/.local/lib/python3.7/site-packages/sqlalchemy/pool/base.py", line 419, in checkout
    rec = pool._do_get()
  File "/home/airflow/.local/lib/python3.7/site-packages/sqlalchemy/pool/impl.py", line 145, in _do_get
    self._dec_overflow()
  File "/home/airflow/.local/lib/python3.7/site-packages/sqlalchemy/util/langhelpers.py", line 72, in __exit__
    with_traceback=exc_tb,
  File "/home/airflow/.local/lib/python3.7/site-packages/sqlalchemy/util/compat.py", line 211, in raise_
    raise exception
  File "/home/airflow/.local/lib/python3.7/site-packages/sqlalchemy/pool/impl.py", line 142, in _do_get
    return self._create_connection()
  File "/home/airflow/.local/lib/python3.7/site-packages/sqlalchemy/pool/base.py", line 247, in _create_connection
    return _ConnectionRecord(self)
  File "/home/airflow/.local/lib/python3.7/site-packages/sqlalchemy/pool/base.py", line 362, in __init__
    self.__connect(first_connect_check=True)
  File "/home/airflow/.local/lib/python3.7/site-packages/sqlalchemy/pool/base.py", line 605, in __connect
    pool.logger.debug("Error on connect(): %s", e)
  File "/home/airflow/.local/lib/python3.7/site-packages/sqlalchemy/util/langhelpers.py", line 72, in __exit__
    with_traceback=exc_tb,
  File "/home/airflow/.local/lib/python3.7/site-packages/sqlalchemy/util/compat.py", line 211, in raise_
    raise exception
  File "/home/airflow/.local/lib/python3.7/site-packages/sqlalchemy/pool/base.py", line 599, in __connect
    connection = pool._invoke_creator(self)
  File "/home/airflow/.local/lib/python3.7/site-packages/sqlalchemy/engine/create.py", line 578, in connect
    return dialect.connect(*cargs, **cparams)
  File "/home/airflow/.local/lib/python3.7/site-packages/sqlalchemy/engine/default.py", line 583, in connect
    return self.dbapi.connect(*cargs, **cparams)
  File "/home/airflow/.local/lib/python3.7/site-packages/psycopg2/__init__.py", line 122, in connect
    conn = _connect(dsn, connection_factory=connection_factory, **kwasync)
psycopg2.OperationalError: could not connect to server: Connection refused
	Is the server running on host "172.23.0.1" and accepting
	TCP/IP connections on port 5435?


The above exception was the direct cause of the following exception:

Traceback (most recent call last):
  File "/home/airflow/.local/lib/python3.7/site-packages/airflow/operators/python.py", line 171, in execute
    return_value = self.execute_callable()
  File "/home/airflow/.local/lib/python3.7/site-packages/airflow/operators/python.py", line 189, in execute_callable
    return self.python_callable(*self.op_args, **self.op_kwargs)
  File "/opt/airflow/dags/etl_dag.py", line 128, in _create_ddl_postgres
    Base.metadata.create_all(engine)
  File "/home/airflow/.local/lib/python3.7/site-packages/sqlalchemy/sql/schema.py", line 4745, in create_all
    ddl.SchemaGenerator, self, checkfirst=checkfirst, tables=tables
  File "/home/airflow/.local/lib/python3.7/site-packages/sqlalchemy/engine/base.py", line 3007, in _run_ddl_visitor
    with self.begin() as conn:
  File "/home/airflow/.local/lib/python3.7/site-packages/sqlalchemy/engine/base.py", line 2923, in begin
    conn = self.connect(close_with_result=close_with_result)
  File "/home/airflow/.local/lib/python3.7/site-packages/sqlalchemy/engine/base.py", line 3095, in connect
    return self._connection_cls(self, close_with_result=close_with_result)
  File "/home/airflow/.local/lib/python3.7/site-packages/sqlalchemy/engine/base.py", line 91, in __init__
    else engine.raw_connection()
  File "/home/airflow/.local/lib/python3.7/site-packages/sqlalchemy/engine/base.py", line 3174, in raw_connection
    return self._wrap_pool_connect(self.pool.connect, _connection)
  File "/home/airflow/.local/lib/python3.7/site-packages/sqlalchemy/engine/base.py", line 3145, in _wrap_pool_connect
    e, dialect, self
  File "/home/airflow/.local/lib/python3.7/site-packages/sqlalchemy/engine/base.py", line 2004, in _handle_dbapi_exception_noconnection
    sqlalchemy_exception, with_traceback=exc_info[2], from_=e
  File "/home/airflow/.local/lib/python3.7/site-packages/sqlalchemy/util/compat.py", line 211, in raise_
    raise exception
  File "/home/airflow/.local/lib/python3.7/site-packages/sqlalchemy/engine/base.py", line 3141, in _wrap_pool_connect
    return fn()
  File "/home/airflow/.local/lib/python3.7/site-packages/sqlalchemy/pool/base.py", line 301, in connect
    return _ConnectionFairy._checkout(self)
  File "/home/airflow/.local/lib/python3.7/site-packages/sqlalchemy/pool/base.py", line 755, in _checkout
    fairy = _ConnectionRecord.checkout(pool)
  File "/home/airflow/.local/lib/python3.7/site-packages/sqlalchemy/pool/base.py", line 419, in checkout
    rec = pool._do_get()
  File "/home/airflow/.local/lib/python3.7/site-packages/sqlalchemy/pool/impl.py", line 145, in _do_get
    self._dec_overflow()
  File "/home/airflow/.local/lib/python3.7/site-packages/sqlalchemy/util/langhelpers.py", line 72, in __exit__
    with_traceback=exc_tb,
  File "/home/airflow/.local/lib/python3.7/site-packages/sqlalchemy/util/compat.py", line 211, in raise_
    raise exception
  File "/home/airflow/.local/lib/python3.7/site-packages/sqlalchemy/pool/impl.py", line 142, in _do_get
    return self._create_connection()
  File "/home/airflow/.local/lib/python3.7/site-packages/sqlalchemy/pool/base.py", line 247, in _create_connection
    return _ConnectionRecord(self)
  File "/home/airflow/.local/lib/python3.7/site-packages/sqlalchemy/pool/base.py", line 362, in __init__
    self.__connect(first_connect_check=True)
  File "/home/airflow/.local/lib/python3.7/site-packages/sqlalchemy/pool/base.py", line 605, in __connect
    pool.logger.debug("Error on connect(): %s", e)
  File "/home/airflow/.local/lib/python3.7/site-packages/sqlalchemy/util/langhelpers.py", line 72, in __exit__
    with_traceback=exc_tb,
  File "/home/airflow/.local/lib/python3.7/site-packages/sqlalchemy/util/compat.py", line 211, in raise_
    raise exception
  File "/home/airflow/.local/lib/python3.7/site-packages/sqlalchemy/pool/base.py", line 599, in __connect
    connection = pool._invoke_creator(self)
  File "/home/airflow/.local/lib/python3.7/site-packages/sqlalchemy/engine/create.py", line 578, in connect
    return dialect.connect(*cargs, **cparams)
  File "/home/airflow/.local/lib/python3.7/site-packages/sqlalchemy/engine/default.py", line 583, in connect
    return self.dbapi.connect(*cargs, **cparams)
  File "/home/airflow/.local/lib/python3.7/site-packages/psycopg2/__init__.py", line 122, in connect
    conn = _connect(dsn, connection_factory=connection_factory, **kwasync)
sqlalchemy.exc.OperationalError: (psycopg2.OperationalError) could not connect to server: Connection refused
	Is the server running on host "172.23.0.1" and accepting
	TCP/IP connections on port 5435?

(Background on this error at: http://sqlalche.me/e/14/e3q8)
[2024-02-01 11:44:00,452] {taskinstance.py:1400} INFO - Marking task as FAILED. dag_id=etl_postgresql, task_id=create_ddl_postgres, execution_date=20240130T230000, start_date=20240201T114239, end_date=20240201T114400
[2024-02-01 11:44:00,466] {standard_task_runner.py:97} ERROR - Failed to execute job 221 for task create_ddl_postgres ((psycopg2.OperationalError) could not connect to server: Connection refused
	Is the server running on host "172.23.0.1" and accepting
	TCP/IP connections on port 5435?

(Background on this error at: http://sqlalche.me/e/14/e3q8); 428)
[2024-02-01 11:44:00,470] {local_task_job.py:221} WARNING - State of this instance has been externally set to failed. Terminating instance.
[2024-02-01 11:44:00,472] {process_utils.py:129} INFO - Sending Signals.SIGTERM to group 428. PIDs of all processes in the group: [428]
[2024-02-01 11:44:00,473] {process_utils.py:80} INFO - Sending the signal Signals.SIGTERM to group 428
[2024-02-01 11:44:00,473] {process_utils.py:75} INFO - Process psutil.Process(pid=428, status='terminated', exitcode=1, started='11:42:39') (428) terminated with exit code 1
